<?xml version="1.0"?>
<robot xmlns:xacro= "http://www.ros.org/wiki/xacro">
    
    <xacro:include filename ="inertial_macros.xacro"/>

    <material name = "acrylic">
        <color rgba="1 1 1 0.3"/>
    </material>

    <material name = "black">
        <color rgba ="0.2 0.2 0.2 1"/>
    </material>

    <!-- Base Link -->
    <link name = "base_link">
    </link>
    
    <!-- BASE_FOOTPRINT_LINK -->
    <joint name = "base_footprint_joint" type = "fixed">
        <parent link = "base_link"/>
        <child link="base_footprint"/>
        <origin xyz = "0 0 0" rpy="0 0 0"/>
    </joint>
    
    <link name = "base_footprint">

    </link>

    <!-- Chassis Link -->
    <joint name = "chassis_joint" type = "fixed">
        <parent link = "base_link"/>
        <child link = "chassis"/>
        <origin xyz = "0 0 0"/>
    </joint>

    <link name = "chassis">
        <visual>
            <origin xyz = "0 0 0.0015"/>
            <geometry>
                <box size = "0.25 0.25 0.003"/>   
            </geometry>
            <material name = "acrylic"/>
        </visual>
        <collision>
            <origin xyz = "0 0 0.0015"/>
            <geometry>
                <box size = "0.25 0.25 0.003"/>   
            </geometry>
        </collision>
        <xacro:inertial_box mass = "0.12" x = "0.25" y = "0.25" z = "0.003">
            <origin xyz = "0 0 0.0015" rpy = "0 0 0"/>
        </xacro:inertial_box>
    </link>

    <gazebo reference="chassis">
        <material>Gazebo/GreyTransparent</material>
    </gazebo>

    <!-- Left Front Wheel Link -->
    <joint name = "left_front_wheel_joint" type = "continuous">
        <parent link = "base_link"/>
        <child link = "left_front_wheel"/>
        <origin xyz = "0.105191 0.137497 -0.01597" rpy = "-${pi/2} 0 0 "/>
        <axis xyz = "0 0 1"/>
    </joint>

    <link name = "left_front_wheel">
        <visual>
            <geometry>
                <cylinder radius="0.0325" length="0.026"/>
            </geometry>
            <material name = "black"/>
        </visual>
        <collision>
            <geometry>
                <sphere radius="0.0325" />
            </geometry>
        </collision>
        <xacro:inertial_cylinder mass = "0.1" length = "0.026" radius = "0.0325">
            <orgin xyz = "0 0 0" rpy = "0 0 0" />
        </xacro:inertial_cylinder>
    </link>

    <gazebo reference="left_front_wheel">
        <material>Gazebo/FlatBlack</material>
    </gazebo>

    <!-- Right Front Wheel Link -->
    <joint name = "right_front_wheel_joint" type = "continuous">
        <parent link = "base_link"/>
        <child link = "right_front_wheel"/>
        <origin xyz = "0.105191 -0.137497 -0.01597" rpy = "${pi/2} 0 0 "/>
        <axis xyz = "0 0 -1"/>
    </joint>

    <link name = "right_front_wheel">
        <visual>
            <geometry>
                <cylinder radius="0.0325" length="0.026"/>
            </geometry>
            <material name = "black"/>
        </visual>
        <collision>
            <geometry>
                <sphere radius="0.0325" />
            </geometry>
        </collision>
        <xacro:inertial_cylinder mass = "0.1" length = "0.026" radius = "0.0325">
            <orgin xyz = "0 0 0" rpy = "0 0 0" />
        </xacro:inertial_cylinder>
    </link>

    <gazebo reference="right_front_wheel">
        <material>Gazebo/FlatBlack</material>        
    </gazebo>

    <!-- Left Back Wheel Link -->
    <joint name = "left_back_wheel_joint" type = "continuous">
        <parent link = "base_link"/>
        <child link = "left_back_wheel"/>
        <origin xyz = "-0.105191 0.137497 -0.01597" rpy = "-${pi/2} 0 0 "/>
        <axis xyz = "0 0 1"/>
    </joint>

    <link name = "left_back_wheel">
        <visual>
            <geometry>
                <cylinder radius="0.0325" length="0.026"/>
            </geometry>
            <material name = "black"/>
        </visual>
        <collision>
            <geometry>
                <sphere radius="0.0325" />
            </geometry>
        </collision>
        <xacro:inertial_cylinder mass = "0.1" length = "0.026" radius = "0.0325">
            <orgin xyz = "0 0 0" rpy = "0 0 0" />
        </xacro:inertial_cylinder>
    </link>

    <gazebo reference="left_back_wheel">
        <material>Gazebo/FlatBlack</material>
    </gazebo>

    <!-- Right Back Wheel Link -->
    <joint name = "right_back_wheel_joint" type = "continuous">
        <parent link = "base_link"/>
        <child link = "right_back_wheel"/>
        <origin xyz = "-0.105191 -0.137497 -0.01597" rpy = "${pi/2} 0 0 "/>
        <axis xyz = "0 0 -1"/>
    </joint>

    <link name = "right_back_wheel">
        <visual>
            <geometry>
                <cylinder radius="0.0325" length="0.026"/>
            </geometry>
            <material name = "black"/>
        </visual>
        <collision>
            <geometry>
                <sphere radius="0.0325" />
            </geometry>
        </collision>
        <xacro:inertial_cylinder mass = "0.1" length = "0.026" radius = "0.0325">
            <orgin xyz = "0 0 0" rpy = "0 0 0" />
        </xacro:inertial_cylinder>
    </link>

    <gazebo reference="right_back_wheel">
        <material>Gazebo/FlatBlack</material>
    </gazebo>

</robot>